<?xml version="1.0"?>
<sdf version="1.4">
  <model name="remy">
    <static>false</static>
    <plugin name="microbrain" filename="libmicromouse_plugin.so"/>
    <link name="chassis">
      <pose>0 0 .02 0 0 0</pose>
  <inertial>
    <mass>2</mass>
    <inertia>
      <ixx>0</ixx>
      <ixy>1</ixy>
      <ixz>1</ixz>
      <iyy>0</iyy>
      <iyz>0</iyz>
      <izz>0</izz>
    </inertia>
  </inertial>
      <collision name="collision">
        <geometry>
          <box>
            <size>0.07 0.054 .02</size>
          </box>
        </geometry>
      </collision>
      <visual name="visual">
        <geometry>
          <box>
            <size>0.07 0.054 .02</size>
          </box>
        </geometry>
      </visual>
      <collision name="caster_collision">
        <pose>-0.02 0 -0.01 0 0 0</pose>
        <geometry>
          <sphere>
            <radius>.01</radius>
          </sphere>
        </geometry>
        <surface>
          <friction>
            <ode>
              <mu>0</mu>
              <mu2>0</mu2>
              <slip1>1.0</slip1>
              <slip2>1.0</slip2>
            </ode>
          </friction>
        </surface>
      </collision>
      <visual name="caster_visual">
        <pose>-0.02 0 -0.01 0 0 0</pose>
        <geometry>
          <sphere>
            <radius>.01</radius>
          </sphere>
        </geometry>
      </visual>
    </link>
    <link name="sensor">
      <sensor type="ray" name="front">
        <!--
        <pose>0 0 .06 0 3.1416 0</pose>
        -->
        <pose>0 0 .06 0 0 0</pose>
        <visualize>true</visualize>
        <update_rate>30</update_rate>
        <always_on>1</always_on>
        <ray>
          <scan>
            <horizontal>
              <samples>30</samples>
              <resolution>1</resolution>
              <min_angle>0.05</min_angle>
              <max_angle>-.05</max_angle>
            </horizontal>
          </scan>
          <range>
            <min>0.02</min>
            <max>0.15</max>
            <resolution>0.001</resolution>
          </range>
          <noise>
            <type>gaussian</type>
            <mean>0.0</mean>
            <stddev>0.001</stddev>
          </noise>
        </ray>
        <plugin name="front_sensor" filename="libgazebo_ros_laser.so">
          <alwaysOn>true</alwaysOn>
          <robotNamespace>remy</robotNamespace>
          <topicName>/sensor/front</topicName>
          <frameName>front</frameName>
        </plugin>
      </sensor>
    </link>
    <link name="left_wheel">
      <pose>0.025 0.034 0.02 0 1.5707 1.5707</pose>
      <collision name="collision">
        <geometry>
          <cylinder>
            <radius>.02</radius>
            <length>.006</length>
          </cylinder>
        </geometry>
      </collision>
      <visual name="visual">
        <geometry>
          <cylinder>
            <radius>.02</radius>
            <length>.006</length>
          </cylinder>
        </geometry>
      </visual>
    </link>
    <link name="right_wheel">
      <pose>0.025 -0.034 0.02 0 1.5707 1.5707</pose>
      <collision name="collision">
        <geometry>
          <cylinder>
            <radius>.02</radius>
            <length>.006</length>
          </cylinder>
        </geometry>
      </collision>
      <visual name="visual">
        <geometry>
          <cylinder>
            <radius>.02</radius>
            <length>.006</length>
          </cylinder>
        </geometry>
      </visual>
    </link>
    <joint type="revolute" name="left_wheel_hinge">
      <pose>0 0 -0.03 0 0 0</pose>
      <child>left_wheel</child>
      <parent>chassis</parent>
      <axis>
        <xyz>0 1 0</xyz>
      </axis>
    </joint>
    <joint type="revolute" name="right_wheel_hinge">
      <pose>0 0 0.03 0 0 0</pose>
      <child>right_wheel</child>
      <parent>chassis</parent>
      <axis>
        <xyz>0 1 0</xyz>
      </axis>
    </joint>
    <plugin name="differential_drive_controller" filename="libgazebo_ros_diff_drive.so">
      <updateRate>1</updateRate>
      <leftJoint>left_wheel_hinge</leftJoint>
      <rightJoint>right_wheel_hinge</rightJoint>
      <wheelSeparation>0.06</wheelSeparation>
      <wheelDiameter>0.04</wheelDiameter>
      <wheelTorque>.5</wheelTorque>
      <commandTopic>cmd_vel</commandTopic>
      <odometryTopic>odom</odometryTopic>
      <odometryFrame>odom</odometryFrame>
      <robotBaseFrame>remy</robotBaseFrame>
      <legacyMode>false</legacyMode>
    </plugin>
  </model>
</sdf>
